<mujoco model="ant_soft">
  <compiler angle="degree" coordinate="local" inertiafromgeom="true"/>
  <!-- Soft contact variant for stable BPTT gradients.
       solref: larger time constant (0.06 vs 0.02) reduces contact stiffness D ~9x
       solimp: wider impedance transition for smoother contacts
       damping: increased to 3 for more dissipative dynamics (bounded eigenvalues)
       All other parameters match ant_substeps4.xml -->
  <option timestep="0.00416667" gravity="0 0 -9.81" solver="Newton" jacobian="dense"/>

  <size njmax="4096" nconmax="1024"/>

  <default>
    <joint armature="0.05" damping="1" limited="true"/>
    <geom condim="3" density="1000.0" friction="1.5 0.1 0.1" margin="0.01"
          solref="0.06 1.2" solimp="0.95 0.99 0.001 0.5 2"
          rgba="0.97 0.38 0.06 1" contype="1" conaffinity="1"/>
  </default>

  <worldbody>
    <geom name="floor" type="plane" size="50 50 1" rgba="0.8 0.9 0.8 1"
          contype="1" conaffinity="1" condim="3"
          solref="0.06 1.2" solimp="0.95 0.99 0.001 0.5 2"/>

    <body name="torso" pos="0 0 0.75">
      <geom name="torso_geom" pos="0 0 0" size="0.25" type="sphere"/>
      <geom fromto="0.0 0.0 0.0 0.2 0.2 0.0" name="aux_1_geom" size="0.08" type="capsule" rgba=".999 .2 .1 1"/>
      <geom fromto="0.0 0.0 0.0 -0.2 0.2 0.0" name="aux_2_geom" size="0.08" type="capsule"/>
      <geom fromto="0.0 0.0 0.0 -0.2 -0.2 0.0" name="aux_3_geom" size="0.08" type="capsule"/>
      <geom fromto="0.0 0.0 0.0 0.2 -0.2 0.0" name="aux_4_geom" size="0.08" type="capsule" rgba=".999 .2 .02 1"/>

      <joint armature="0" damping="0" limited="false" margin="0.01" name="root" pos="0 0 0" type="free"/>

      <body name="front_left_leg" pos="0.2 0.2 0">
        <joint axis="0 0 1" name="hip_1" pos="0.0 0.0 0.0" range="-40 40" type="hinge"/>
        <geom fromto="0.0 0.0 0.0 0.2 0.2 0.0" name="left_leg_geom" size="0.08" type="capsule" rgba=".999 .2 .1 1"/>
        <body pos="0.2 0.2 0" name="front_left_foot">
          <joint axis="-1 1 0" name="ankle_1" pos="0.0 0.0 0.0" range="30 100" type="hinge"/>
          <geom fromto="0.0 0.0 0.0 0.4 0.4 0.0" name="left_ankle_geom" size="0.08" type="capsule" rgba=".999 .2 .1 1"/>
        </body>
      </body>

      <body name="front_right_leg" pos="-0.2 0.2 0">
        <joint axis="0 0 1" name="hip_2" pos="0.0 0.0 0.0" range="-40 40" type="hinge"/>
        <geom fromto="0.0 0.0 0.0 -0.2 0.2 0.0" name="right_leg_geom" size="0.08" type="capsule"/>
        <body pos="-0.2 0.2 0" name="front_right_foot">
          <joint axis="1 1 0" name="ankle_2" pos="0.0 0.0 0.0" range="-100 -30" type="hinge"/>
          <geom fromto="0.0 0.0 0.0 -0.4 0.4 0.0" name="right_ankle_geom" size="0.08" type="capsule"/>
        </body>
      </body>

      <body name="left_back_leg" pos="-0.2 -0.2 0">
        <joint axis="0 0 1" name="hip_3" pos="0.0 0.0 0.0" range="-40 40" type="hinge"/>
        <geom fromto="0.0 0.0 0.0 -0.2 -0.2 0.0" name="back_leg_geom" size="0.08" type="capsule"/>
        <body pos="-0.2 -0.2 0" name="left_back_foot">
          <joint axis="-1 1 0" name="ankle_3" pos="0.0 0.0 0.0" range="-100 -30" type="hinge"/>
          <geom fromto="0.0 0.0 0.0 -0.4 -0.4 0.0" name="third_ankle_geom" size="0.08" type="capsule"/>
        </body>
      </body>

      <body name="right_back_leg" pos="0.2 -0.2 0">
        <joint axis="0 0 1" name="hip_4" pos="0.0 0.0 0.0" range="-40 40" type="hinge"/>
        <geom fromto="0.0 0.0 0.0 0.2 -0.2 0.0" name="rightback_leg_geom" size="0.08" type="capsule" rgba=".999 .2 .1 1"/>
        <body pos="0.2 -0.2 0" name="right_back_foot">
          <joint axis="1 1 0" name="ankle_4" pos="0.0 0.0 0.0" range="30 100" type="hinge"/>
          <geom fromto="0.0 0.0 0.0 0.4 -0.4 0.0" name="fourth_ankle_geom" size="0.08" type="capsule" rgba=".999 .2 .1 1"/>
        </body>
      </body>
    </body>
  </worldbody>

  <actuator>
    <motor joint="hip_4" gear="200"/>
    <motor joint="ankle_4" gear="200"/>
    <motor joint="hip_1" gear="200"/>
    <motor joint="ankle_1" gear="200"/>
    <motor joint="hip_2" gear="200"/>
    <motor joint="ankle_2" gear="200"/>
    <motor joint="hip_3" gear="200"/>
    <motor joint="ankle_3" gear="200"/>
  </actuator>

  <keyframe>
    <key name="standing" qpos="0 0 0.75 1 0 0 0 0 1 0 -1 0 -1 0 1"
         qvel="0 0 0 0 0 0 0 0 0 0 0 0 0 0"/>
  </keyframe>
</mujoco>
